Workbook

Sheet Raw Data (Dirty)
A1: Order_ID | B1: Date | C1: Customer_Name | D1: Category | E1: Product | F1: Quantity | G1: Unit_Price | H1: Region | I1: Payment_Method | J1: Order_Status | K1: Discount_Pct | L1: Return_Flag
A2: ORD-2001 | B2: 2024-03-11 | C2: Sneha Patel | D2: Toys | E2: Lego Set | F2: 5 | G2: 3888.46 | H2: Central | I2: Cash on Delivery | J2: Delivered | K2: 5 | L2: No
A3: ORD-2002 | B3: 2024-06-22 | C3: Nisha Tiwari | D3: Books | E3: Python Book | F3: 1 | G3: 6708.09 | H3: West | I3: Credit Card | J3: Delivered | K3: 5 | L3: Yes
A4: ORD-2002 | B4: 2024-06-22 | C4: Nisha Tiwari | D4: Books | E4: Python Book | F4: 1 | G4: 6708.09 | H4: West | I4: Credit Card | J4: Delivered | K4: 5 | L4: Yes
A5: ORD-2003 | B5: 2024-03-11 | C5: Deepak Joshi | D5: Clothing | E5: Kurta | F5: 9 | G5: 3836.86 | I5: Credit Card | J5: Delivered | K5: 0 | L5: No
A6: ORD-2004 | B6: 2024-02-23 | D6: Toys | E6: Puzzle | F6: 9 | G6: 748.95 | H6: South | I6: Debit Card | J6: Delivered | K6: 0 | L6: No
A7: ORD-2005 | B7: 2024-04-27 | C7: Arjun Das | D7: Books | E7: Self-Help | F7: -2 | G7: 2284.6 | H7: Central | I7: UPI | J7: Delivered | K7: 10 | L7: No
A8: ORD-2006 | B8: 2024-04-25 | C8: Meera Iyer | D8: TOYS | E8: Puzzle | F8: 4 | G8: 1870.4 | H8: West | I8: Net Banking | J8: Delivered | K8: 5 | L8: Yes
A9: ORD-2007 | B9: 2024-01-02 | C9: Amit Sharma | D9: electronics | E9: Headphones | F9: 7 | G9: 1075.5 | H9: Central | I9: Cash on Delivery | J9: Delivered | K9: 15 | L9: No
A10: ORD-2008 | B10: 2024-04-27 | C10: Priya Singh | D10: Beauty | E10: Shampoo | F10: 5 | G10: 4319.73 | H10: North | I10: Net Banking | J10: Shipped | K10: 10 | L10: Yes
A11: ORD-2009 | B11: 02/01/2024 | C11: Rahul Verma | D11: Books | E11: Fiction Novel | F11: 1 | G11: 2033.26 | H11: West | I11: UPI | J11: Shipped | K11: 15 | L11: Yes
A12: ORD-2010 | B12: 2024-02-08 | C12: Arjun Das | D12: Electronics | E12: Smartphone | F12: 3 | G12: 1439.35 | H12: North | I12: UPI | J12: Delivered | L12: Yes
A13: ORD-2011 | B13: 2024-06-24 | C13: Pooja Nair | D13: Books | E13: Self-Help | F13: 5 | G13: 4846.38 | H13: North | J13: Shipped | K13: 20 | L13: Yes
A14: ORD-2012 | B14: 2024-05-09 | C14: Nisha Tiwari | D14: Home & Kitchen | E14: Pressure Cooker | F14: 1 | G14: 4795.91 | H14: North | I14: UPI | J14: shipped | K14: 0 | L14: No
A15: ORD-2013 | B15: 2024-01-22 | C15: Deepak Joshi | D15: Electronics | E15: Laptop | F15: 2 | G15: 6265.56 | H15: South | I15: UPI | J15: Processing | K15: 15
A16: ORD-2014 | B16: 2024-04-18 | C16: Arjun Das | D16: Sports | E16: Dumbbells | F16: 4 | G16: 0 | H16: West | I16: Debit Card | J16: Shipped | K16: 10 | L16: No
A17: ORD-2015 | B17: 2024-05-11 | C17: Sneha Patel | D17: Toys | E17: RC Car | F17: 6 | G17: 6075.61 | H17: West | I17: Cash on Delivery | K17: 15 | L17: Yes
A18: ORD-2016 | B18: 2024-03-13 | C18: Rohit Yadav | D18: Toys | E18: PUZZLE | F18: 5 | G18: 7410.48 | H18: East | I18: UPI | J18: Cancelled | K18: 5 | L18: Yes
A19: ORD-2017 | B19: 2024-03-26 | C19: Sneha Patel | E19: Jacket | F19: 10 | G19: 4554.08 | H19: Central | I19: UPI | J19: Shipped | K19: 20 | L19: No
A20: ORD-2018 | B20: 2024-06-19 | C20: Kavya Reddy | D20: Toys | E20: Board Game | F20: 5 | G20: 6385.6 | H20: East | I20: UPI | J20: Delivered | K20: 20 | L20: Yes
A21: ORD-2019 | B21: 2024-06-10 | C21: Pooja Nair | D21: Electronics | E21: Tablet | F21: 1 | G21: 520.19 | H21: South | I21: Net Banking | J21: Delivered | K21: 15 | L21: No
A22: ORD-2019 | B22: 2024-06-10 | C22: Pooja Nair | D22: Electronics | E22: Tablet | F22: 1 | G22: 520.19 | H22: South | I22: Net Banking | J22: Delivered | K22: 15 | L22: No
A23: ORD-2020 | B23: 2024-01-04 | C23: Arjun Das | D23: Sports | E23: Football | F23: 1 | G23: 7378.87 | I23: Cash on Delivery | J23: Delivered | K23: 10 | L23: No
A24: ORD-2021 | B24: 2024-06-03 | D24: Books | E24: Comics | F24: 9 | G24: 5760.9 | H24: South | I24: Net Banking | J24: Delivered | K24: 5 | L24: No
A25: ORD-2022 | B25: 2024-04-08 | C25: Meera Iyer | D25: Home & Kitchen | E25: Curtain | F25: -10 | G25: 3185.22 | H25: Central | I25: Credit Card | J25: Delivered | K25: 15 | L25: No
A26: ORD-2023 | B26: 2024-05-21 | C26: Karan Mehta | D26: CLOTHING | E26: Kurta | F26: 6 | G26: 7724.34 | H26: West | I26: Credit Card | J26: Cancelled | K26: 20 | L26: Yes
A27: ORD-2024 | B27: 2024-03-26 | C27: Karan Mehta | D27: books | E27: Python Book | F27: 4 | G27: 7517.99 | H27: East | I27: Credit Card | J27: Shipped | K27: 10 | L27: Yes
A28: ORD-2025 | B28: 2024-03-16 | C28: Priya Singh | D28: Home & Kitchen | E28: Curtain | F28: 10 | G28: 5501.84 | H28: East | I28: Debit Card | J28: Delivered | K28: 5 | L28: No
A29: ORD-2026 | B29: 14/05/2024 | C29: Deepak Joshi | D29: Home & Kitchen | E29: Water Bottle | F29: 7 | G29: 5576.36 | H29: North | I29: Net Banking | J29: Delivered | K29: 20 | L29: No
A30: ORD-2027 | B30: 2024-04-13 | C30: Vikas Gupta | D30: Sports | E30: Dumbbells | F30: 9 | G30: 3522.31 | H30: East | I30: UPI | J30: Processing | L30: No
A31: ORD-2028 | B31: 2024-04-17 | C31: Suresh Kumar | D31: Home & Kitchen | E31: Water Bottle | F31: 1 | G31: 4674.6 | H31: West | J31: Processing | K31: 10 | L31: No
A32: ORD-2029 | B32: 2024-01-12 | C32: Priya Singh | D32: Books | E32: Comics | F32: 3 | G32: 1449.2 | H32: West | I32: Cash on Delivery | J32: CANCELLED | K32: 10 | L32: No
A33: ORD-2030 | B33: 2024-01-22 | C33: Arjun Das | D33: Home & Kitchen | E33: Pressure Cooker | F33: 3 | G33: 2733.93 | H33: North | I33: Net Banking | J33: Delivered | K33: 20
A34: ORD-2031 | B34: 2024-06-14 | C34: Kavya Reddy | D34: Books | E34: Self-Help | F34: 1 | G34: 0 | H34: West | I34: UPI | J34: Delivered | K34: 20 | L34: Yes
A35: ORD-2032 | B35: 2024-01-01 | C35: Anjali Roy | D35: Electronics | E35: Smartwatch | F35: 8 | G35: 2331.29 | H35: Central | I35: UPI | K35: 5 | L35: No
A36: ORD-2033 | B36: 2024-02-19 | C36: Kavya Reddy | D36: Books | E36: FICTION NOVEL | F36: 10 | G36: 7626.19 | H36: South | I36: Credit Card | J36: Processing | K36: 20 | L36: No
A37: ORD-2034 | B37: 2024-03-10 | C37: Deepak Joshi | E37: Water Bottle | F37: 2 | G37: 4247.37 | H37: East | I37: Net Banking | J37: Delivered | K37: 15 | L37: No
A38: ORD-2035 | B38: 2024-05-16 | C38: Vikas Gupta | D38: Electronics | E38: Smartwatch | F38: 10 | G38: 3777.82 | H38: East | I38: Credit Card | J38: Delivered | K38: 0 | L38: Yes
A39: ORD-2036 | B39: 2024-03-26 | C39: Anjali Roy | D39: Clothing | E39: Kurta | F39: 6 | G39: 7535.44 | H39: East | I39: Debit Card | J39: Shipped | K39: 5 | L39: No
A40: ORD-2036 | B40: 2024-03-26 | C40: Anjali Roy | D40: Clothing | E40: Kurta | F40: 6 | G40: 7535.44 | H40: East | I40: Debit Card | J40: Shipped | K40: 5 | L40: No
...

Sheet Data Cleaning Log
A1: 📋 DATA CLEANING LOG — All Problems & Solutions
A2: # | B2: Problem Type | C2: Column | D2: Count | F2: Action Taken
A3: 1 | B3: Duplicate Rows | C3: All | D3: ~15 rows | F3: Removed all duplicate Order IDs, kept first occurrence only
A4: 2 | B4: Null Region | C4: H (Region) | D4: ~8 cells | F4: All blank Region cells filled with 'Unknown'
A5: 3 | B5: Null Customer Name | C5: C (Customer_Name) | D5: ~5 cells | F5: Blank names replaced with 'Guest User'
A6: 4 | B6: Negative Quantity | C6: F (Quantity) | D6: ~5 cells | F6: All negative quantities converted to positive using ABS()
A7: 5 | B7: UPPERCASE Category | C7: D (Category) | D7: ~6 cells | F7: Standardised to Title Case using PROPER()
A8: 6 | B8: lowercase category | C8: D (Category) | D8: ~5 cells | F8: Standardised to Title Case using PROPER()
A9: 7 | B9: Extra Spaces in Name | C9: C (Customer_Name) | D9: ~4 cells | F9: Leading & trailing spaces removed using TRIM()
A10: 8 | B10: Mixed Date Format DD/MM/YYYY | C10: B (Date) | D10: ~7 cells | F10: All dates standardised to YYYY-MM-DD format
A11: 9 | B11: Null Discount | C11: K (Discount_Pct) | D11: ~6 cells | F11: Blank discounts filled with 0 (no discount assumed)
A12: 10 | B12: Null Payment Method | C12: I (Payment_Method) | D12: ~5 cells | F12: Missing payment methods replaced with 'Unknown'
A13: 11 | B13: Typo in Order Status | C13: J (Order_Status) | D13: ~7 cells | F13: All status values corrected & standardised
A14: 12 | B14: Null Return Flag | C14: L (Return_Flag) | D14: ~5 cells | F14: Blank return flags filled with 'No' (not returned by default)
... A17: 15 | B17: UPPERCASE Product Name | C17: E (Product) | D17: ~5 cells | F17: Product names standardised to Title Case
A18: TOTAL ISSUES CLEANED | D18: 15 Types | E18: ✅ All 15 issues resolved — Data is clean & ready for analysis

Sheet Cleaned Data
A1: Order_ID | B1: Date | C1: Customer_Name | D1: Category | E1: Product | F1: Quantity | G1: Unit_Price | H1: Total_Sale | I1: Discount_Pct | J1: Net_Sale | K1: Region | L1: Payment_Method | M1: Order_Status | N1: Return_Flag
A2: ORD-3001 | B2: 2024-01-01 | C2: Sneha Patel | D2: Beauty | E2: Shampoo | F2: 3 | G2: 5931.3 | H2: =F2*G2 -> 17793.9 | I2: 0.2 | J2: =H2*(1-I2) -> 14235.12 | K2: Central | L2: UPI | M2: Shipped | N2: Yes
A3: ORD-3002 | B3: 2024-01-03 | C3: Deepak Joshi | D3: Electronics | E3: Tablet | F3: 1 | G3: 4555.77 | H3: =F3*G3 -> 4555.77 | I3: 0.05 | J3: =H3*(1-I3) -> 4327.9815 | K3: Central | L3: Net Banking | M3: Delivered | N3: Yes
A4: ORD-3003 | B4: 2024-03-26 | C4: Arjun Das | D4: Books | E4: UPSC Guide | F4: 7 | G4: 2820.97 | H4: =F4*G4 -> 19746.79 | I4: 0.1 | J4: =H4*(1-I4) -> 17772.111 | K4: South | L4: Credit Card | M4: Processing | N4: No
A5: ORD-3004 | B5: 2024-04-04 | C5: Anjali Roy | D5: Electronics | E5: Tablet | F5: 5 | G5: 6485.96 | H5: =F5*G5 -> 32429.8 | I5: 0 | J5: =H5*(1-I5) -> 32429.8 | K5: West | L5: Cash on Delivery | M5: Delivered | N5: Yes
A6: ORD-3005 | B6: 2024-05-10 | C6: Meera Iyer | D6: Electronics | E6: Headphones | F6: 10 | G6: 1659.47 | H6: =F6*G6 -> 16594.7 | I6: 0.05 | J6: =H6*(1-I6) -> 15764.965 | K6: North | L6: UPI | M6: Processing | N6: No
A7: ORD-3006 | B7: 2024-02-28 | C7: Karan Mehta | D7: Electronics | E7: Smartwatch | F7: 6 | G7: 1426.83 | H7: =F7*G7 -> 8560.98 | I7: 0.1 | J7: =H7*(1-I7) -> 7704.882 | K7: East | L7: Credit Card | M7: Delivered | N7: No
A8: ORD-3007 | B8: 2024-06-06 | C8: Sneha Patel | D8: Books | E8: UPSC Guide | F8: 8 | G8: 3128.73 | H8: =F8*G8 -> 25029.84 | I8: 0.1 | J8: =H8*(1-I8) -> 22526.856 | K8: Central | L8: Credit Card | M8: Delivered | N8: No
A9: ORD-3008 | B9: 2024-01-26 | C9: Karan Mehta | D9: Clothing | E9: T-Shirt | F9: 4 | G9: 7318.12 | H9: =F9*G9 -> 29272.48 | I9: 0.05 | J9: =H9*(1-I9) -> 27808.856 | K9: Central | L9: Debit Card | M9: Delivered | N9: Yes
A10: ORD-3009 | B10: 2024-06-15 | C10: Rahul Verma | D10: Sports | E10: Football | F10: 9 | G10: 4380.97 | H10: =F10*G10 -> 39428.73 | I10: 0.2 | J10: =H10*(1-I10) -> 31542.984 | K10: Central | L10: Net Banking | M10: Delivered | N10: Yes
A11: ORD-3010 | B11: 2024-02-05 | C11: Priya Singh | D11: Home & Kitchen | E11: Mixer | F11: 2 | G11: 1349.8 | H11: =F11*G11 -> 2699.6 | I11: 0.2 | J11: =H11*(1-I11) -> 2159.68 | K11: South | L11: Net Banking | M11: Delivered | N11: No
A12: ORD-3011 | B12: 2024-04-20 | C12: Deepak Joshi | D12: Sports | E12: Yoga Mat | F12: 9 | G12: 6907.12 | H12: =F12*G12 -> 62164.08 | I12: 0.2 | J12: =H12*(1-I12) -> 49731.264 | K12: North | L12: UPI | M12: Cancelled | N12: Yes
A13: ORD-3012 | B13: 2024-03-25 | C13: Priya Singh | D13: Toys | E13: RC Car | F13: 7 | G13: 1391.54 | H13: =F13*G13 -> 9740.78 | I13: 0.2 | J13: =H13*(1-I13) -> 7792.624 | K13: North | L13: Debit Card | M13: Shipped | N13: No
... A81: ORD-3080 | B81: 2024-01-25 | C81: Pooja Nair | D81: Books | E81: Self-Help | F81: 8 | G81: 7341.17 | H81: =F81*G81 -> 58729.36 | I81: 0.15 | J81: =H81*(1-I81) -> 49919.956 | K81: South | L81: Cash on Delivery | M81: Shipped | N81: Yes

Sheet Summary & KPIs
A1: E-COMMERCE SALES — SUMMARY & KPI TRACKER (Cleaned Data)
A3: KPI Metric | B3: Value | D3: Category | E3: Orders | F3: Revenue (₹) | G3: % Share | H3: Avg Disc
A4: Total Orders (After Cleaning) | B4: =COUNTA('Cleaned Data'!A2:A81) -> 80 | D4: Electronics | E4: =COUNTIF('Cleaned Data'!D2:D81,D4) -> 11 | F4: =SUMIF('Cleaned Data'!D2:D81,D4,'Cleaned Data'!J2:J81) -> 150538.22 | G4: =IFERROR(F4/SUM(F4:F10),0) -> 0.11197568 | H4: =IFERROR(AVERAGEIF('Cleaned Data'!D2:D81,D4,'Cleaned Data'!I2:I81),0) -> 0.11363636
A5: Total Revenue (₹) | B5: =SUM('Cleaned Data'!J2:J81) -> 1344383.2 | D5: Clothing | E5: =COUNTIF('Cleaned Data'!D2:D81,D5) -> 6 | F5: =SUMIF('Cleaned Data'!D2:D81,D5,'Cleaned Data'!J2:J81) -> 100583.61 | G5: =IFERROR(F5/SUM(F4:F10),0) -> 0.074817668 | H5: =IFERROR(AVERAGEIF('Cleaned Data'!D2:D81,D5,'Cleaned Data'!I2:I81),0) -> 0.091666667
A6: Average Order Value (₹) | B6: =IFERROR(B5/B4,0) -> 16804.79 | D6: Home & Kitchen | E6: =COUNTIF('Cleaned Data'!D2:D81,D6) -> 12 | F6: =SUMIF('Cleaned Data'!D2:D81,D6,'Cleaned Data'!J2:J81) -> 154897.41 | G6: =IFERROR(F6/SUM(F4:F10),0) -> 0.1152182 | H6: =IFERROR(AVERAGEIF('Cleaned Data'!D2:D81,D6,'Cleaned Data'!I2:I81),0) -> 0.10416667
A7: Total Units Sold | B7: =SUM('Cleaned Data'!F2:F81) -> 392 | D7: Sports | E7: =COUNTIF('Cleaned Data'!D2:D81,D7) -> 16 | F7: =SUMIF('Cleaned Data'!D2:D81,D7,'Cleaned Data'!J2:J81) -> 366472.91 | G7: =IFERROR(F7/SUM(F4:F10),0) -> 0.27259558 | H7: =IFERROR(AVERAGEIF('Cleaned Data'!D2:D81,D7,'Cleaned Data'!I2:I81),0) -> 0.09375
A8: Cancelled Orders | B8: =COUNTIF('Cleaned Data'!M2:M81,"Cancelled") -> 6 | D8: Books | E8: =COUNTIF('Cleaned Data'!D2:D81,D8) -> 13 | F8: =SUMIF('Cleaned Data'!D2:D81,D8,'Cleaned Data'!J2:J81) -> 241561.65 | G8: =IFERROR(F8/SUM(F4:F10),0) -> 0.17968214 | H8: =IFERROR(AVERAGEIF('Cleaned Data'!D2:D81,D8,'Cleaned Data'!I2:I81),0) -> 0.10769231
A9: Return Rate (%) | B9: =IFERROR(COUNTIF('Cleaned Data'!N2:N81,"Yes")/B4,0) -> 0.4375 | D9: Beauty | E9: =COUNTIF('Cleaned Data'!D2:D81,D9) -> 10 | F9: =SUMIF('Cleaned Data'!D2:D81,D9,'Cleaned Data'!J2:J81) -> 169204.68 | G9: =IFERROR(F9/SUM(F4:F10),0) -> 0.12586046 | H9: =IFERROR(AVERAGEIF('Cleaned Data'!D2:D81,D9,'Cleaned Data'!I2:I81),0) -> 0.07
A10: Delivered Orders | B10: =COUNTIF('Cleaned Data'!M2:M81,"Delivered") -> 43 | D10: Toys | E10: =COUNTIF('Cleaned Data'!D2:D81,D10) -> 12 | F10: =SUMIF('Cleaned Data'!D2:D81,D10,'Cleaned Data'!J2:J81) -> 161124.68 | G10: =IFERROR(F10/SUM(F4:F10),0) -> 0.11985027 | H10: =IFERROR(AVERAGEIF('Cleaned Data'!D2:D81,D10,'Cleaned Data'!I2:I81),0) -> 0.10833333
A11: Average Discount Given | B11: =IFERROR(AVERAGE('Cleaned Data'!I2:I81),0) -> 0.099375 | D11: TOTAL | E11: =SUM(E4:E10) -> 80 | F11: =SUM(F4:F10) -> 1344383.2
A13: Region | B13: Revenue (₹) | D13: Payment Method | E13: Orders
A14: North | B14: =SUMIF('Cleaned Data'!K2:K81,A14,'Cleaned Data'!J2:J81) -> 279954.78 | D14: UPI | E14: =COUNTIF('Cleaned Data'!L2:L81,D14) -> 14
A15: South | B15: =SUMIF('Cleaned Data'!K2:K81,A15,'Cleaned Data'!J2:J81) -> 291779.98 | D15: Credit Card | E15: =COUNTIF('Cleaned Data'!L2:L81,D15) -> 16
A16: East | B16: =SUMIF('Cleaned Data'!K2:K81,A16,'Cleaned Data'!J2:J81) -> 149232.9 | D16: Debit Card | E16: =COUNTIF('Cleaned Data'!L2:L81,D16) -> 20
A17: West | B17: =SUMIF('Cleaned Data'!K2:K81,A17,'Cleaned Data'!J2:J81) -> 236970.9 | D17: Net Banking | E17: =COUNTIF('Cleaned Data'!L2:L81,D17) -> 12
A18: Central | B18: =SUMIF('Cleaned Data'!K2:K81,A18,'Cleaned Data'!J2:J81) -> 386444.61 | D18: Cash on Delivery | E18: =COUNTIF('Cleaned Data'!L2:L81,D18) -> 18

Sheet Dashboard
A1: E-COMMERCE DASHBOARD | Cleaned Data | Jan–Jun 2024 | O1: E-COMMERCE DASHBOARD | Cleaned Data | Jan–Jun 2025

Sheet Product Lookup
A1: 🔍 ORDER LOOKUP TOOL — Type Order ID in Yellow Cell
A3: Enter Order ID: | B3: ORD-3001
A5: Date | B5: =IFERROR(INDEX('Cleaned Data'!B2:B81,MATCH(B3,'Cleaned Data'!A2:A81,0)),"Not Found") -> 2024-01-01
A6: Customer Name | B6: =IFERROR(INDEX('Cleaned Data'!C2:C81,MATCH(B3,'Cleaned Data'!A2:A81,0)),"Not Found") -> Sneha Patel
A7: Category | B7: =IFERROR(INDEX('Cleaned Data'!D2:D81,MATCH(B3,'Cleaned Data'!A2:A81,0)),"Not Found") -> Beauty
A8: Product | B8: =IFERROR(INDEX('Cleaned Data'!E2:E81,MATCH(B3,'Cleaned Data'!A2:A81,0)),"Not Found") -> Shampoo
A9: Quantity | B9: =IFERROR(INDEX('Cleaned Data'!F2:F81,MATCH(B3,'Cleaned Data'!A2:A81,0)),"Not Found") -> 3
A10: Unit Price (₹) | B10: =IFERROR(INDEX('Cleaned Data'!G2:G81,MATCH(B3,'Cleaned Data'!A2:A81,0)),"Not Found") -> 5931.3
A11: Net Sale (₹) | B11: =IFERROR(INDEX('Cleaned Data'!J2:J81,MATCH(B3,'Cleaned Data'!A2:A81,0)),"Not Found") -> 14235.12
A12: Region | B12: =IFERROR(INDEX('Cleaned Data'!K2:K81,MATCH(B3,'Cleaned Data'!A2:A81,0)),"Not Found") -> Central
A13: Payment Method | B13: =IFERROR(INDEX('Cleaned Data'!L2:L81,MATCH(B3,'Cleaned Data'!A2:A81,0)),"Not Found") -> UPI
A14: Order Status | B14: =IFERROR(INDEX('Cleaned Data'!M2:M81,MATCH(B3,'Cleaned Data'!A2:A81,0)),"Not Found") -> Shipped
A15: Return Flag | B15: =IFERROR(INDEX('Cleaned Data'!N2:N81,MATCH(B3,'Cleaned Data'!A2:A81,0)),"Not Found") -> Yes

Sheet Monthly Trend
A1: MONTHLY SALES TREND — 2024
A3: Month | B3: Orders | C3: Revenue (₹) | D3: Avg Order Value | E3: MoM Growth (%)
A4: January | B4: =COUNTIFS('Cleaned Data'!B2:B81,"2024-01-*") -> 13 | C4: =SUMPRODUCT((LEFT('Cleaned Data'!B2:B81,7)="2024-01")*'Cleaned Data'!J2:J81) -> 262296.82 | D4: =IFERROR(C4/B4,0) -> 20176.678 | E4: —
A5: February | B5: =COUNTIFS('Cleaned Data'!B2:B81,"2024-02-*") -> 18 | C5: =SUMPRODUCT((LEFT('Cleaned Data'!B2:B81,7)="2024-02")*'Cleaned Data'!J2:J81) -> 217848.77 | D5: =IFERROR(C5/B5,0) -> 12102.709 | E5: =IFERROR((C5-C4)/C4,0) -> -0.16945709
A6: March | B6: =COUNTIFS('Cleaned Data'!B2:B81,"2024-03-*") -> 8 | C6: =SUMPRODUCT((LEFT('Cleaned Data'!B2:B81,7)="2024-03")*'Cleaned Data'!J2:J81) -> 171616.06 | D6: =IFERROR(C6/B6,0) -> 21452.007 | E6: =IFERROR((C6-C5)/C5,0) -> -0.21222387
A7: April | B7: =COUNTIFS('Cleaned Data'!B2:B81,"2024-04-*") -> 14 | C7: =SUMPRODUCT((LEFT('Cleaned Data'!B2:B81,7)="2024-04")*'Cleaned Data'!J2:J81) -> 257550.22 | D7: =IFERROR(C7/B7,0) -> 18396.444 | E7: =IFERROR((C7-C6)/C6,0) -> 0.500735
A8: May | B8: =COUNTIFS('Cleaned Data'!B2:B81,"2024-05-*") -> 14 | C8: =SUMPRODUCT((LEFT('Cleaned Data'!B2:B81,7)="2024-05")*'Cleaned Data'!J2:J81) -> 244122.54 | D8: =IFERROR(C8/B8,0) -> 17437.324 | E8: =IFERROR((C8-C7)/C7,0) -> -0.052136171
A9: June | B9: =COUNTIFS('Cleaned Data'!B2:B81,"2024-06-*") -> 13 | C9: =SUMPRODUCT((LEFT('Cleaned Data'!B2:B81,7)="2024-06")*'Cleaned Data'!J2:J81) -> 190948.76 | D9: =IFERROR(C9/B9,0) -> 14688.366 | E9: =IFERROR((C9-C8)/C8,0) -> -0.21781593
A10: TOTAL | B10: =SUM(B4:B9) -> 80 | C10: =SUM(C4:C9) -> 1344383.2

Sheet Top Products
A1: 🏆 PRODUCT PERFORMANCE RANKING — Color Scale Applied
A3: Product | B3: Category | C3: Orders | D3: Revenue (₹) | E3: Avg Price (₹) | F3: Performance
A4: Smartphone | B4: Electronics | C4: =COUNTIF('Cleaned Data'!E2:E81,A4) -> 1 | D4: =SUMIF('Cleaned Data'!E2:E81,A4,'Cleaned Data'!J2:J81) -> 3601.773 | E4: =IFERROR(AVERAGEIF('Cleaned Data'!E2:E81,A4,'Cleaned Data'!G2:G81),0) -> 706.23 | F4: =IF(D4>5000,"⭐ High",IF(D4>2000,"✅ Medium","🔻 Low")) -> ✅ Medium
A5: Laptop | B5: Electronics | C5: =COUNTIF('Cleaned Data'!E2:E81,A5) -> 1 | D5: =SUMIF('Cleaned Data'!E2:E81,A5,'Cleaned Data'!J2:J81) -> 11937.092 | E5: =IFERROR(AVERAGEIF('Cleaned Data'!E2:E81,A5,'Cleaned Data'!G2:G81),0) -> 6282.68 | F5: =IF(D5>5000,"⭐ High",IF(D5>2000,"✅ Medium","🔻 Low")) -> ⭐ High
A6: Headphones | B6: Electronics | C6: =COUNTIF('Cleaned Data'!E2:E81,A6) -> 2 | D6: =SUMIF('Cleaned Data'!E2:E81,A6,'Cleaned Data'!J2:J81) -> 17470.333 | E6: =IFERROR(AVERAGEIF('Cleaned Data'!E2:E81,A6,'Cleaned Data'!G2:G81),0) -> 1185.02 | F6: =IF(D6>5000,"⭐ High",IF(D6>2000,"✅ Medium","🔻 Low")) -> ⭐ High
A7: Smartwatch | B7: Electronics | C7: =COUNTIF('Cleaned Data'!E2:E81,A7) -> 3 | D7: =SUMIF('Cleaned Data'!E2:E81,A7,'Cleaned Data'!J2:J81) -> 20889.974 | E7: =IFERROR(AVERAGEIF('Cleaned Data'!E2:E81,A7,'Cleaned Data'!G2:G81),0) -> 3477.1033 | F7: =IF(D7>5000,"⭐ High",IF(D7>2000,"✅ Medium","🔻 Low")) -> ⭐ High
A8: Tablet | B8: Electronics | C8: =COUNTIF('Cleaned Data'!E2:E81,A8) -> 4 | D8: =SUMIF('Cleaned Data'!E2:E81,A8,'Cleaned Data'!J2:J81) -> 96639.049 | E8: =IFERROR(AVERAGEIF('Cleaned Data'!E2:E81,A8,'Cleaned Data'!G2:G81),0) -> 6068.6 | F8: =IF(D8>5000,"⭐ High",IF(D8>2000,"✅ Medium","🔻 Low")) -> ⭐ High
A9: T-Shirt | B9: Clothing | C9: =COUNTIF('Cleaned Data'!E2:E81,A9) -> 2 | D9: =SUMIF('Cleaned Data'!E2:E81,A9,'Cleaned Data'!J2:J81) -> 50978.036 | E9: =IFERROR(AVERAGEIF('Cleaned Data'!E2:E81,A9,'Cleaned Data'!G2:G81),0) -> 7520.59 | F9: =IF(D9>5000,"⭐ High",IF(D9>2000,"✅ Medium","🔻 Low")) -> ⭐ High
A10: Jeans | B10: Clothing | C10: =COUNTIF('Cleaned Data'!E2:E81,A10) -> 1 | D10: =SUMIF('Cleaned Data'!E2:E81,A10,'Cleaned Data'!J2:J81) -> 5791.407 | E10: =IFERROR(AVERAGEIF('Cleaned Data'!E2:E81,A10,'Cleaned Data'!G2:G81),0) -> 3406.71 | F10: =IF(D10>5000,"⭐ High",IF(D10>2000,"✅ Medium","🔻 Low")) -> ⭐ High
A11: Kurta | B11: Clothing | C11: =COUNTIF('Cleaned Data'!E2:E81,A11) -> 2 | D11: =SUMIF('Cleaned Data'!E2:E81,A11,'Cleaned Data'!J2:J81) -> 39514.812 | E11: =IFERROR(AVERAGEIF('Cleaned Data'!E2:E81,A11,'Cleaned Data'!G2:G81),0) -> 3867.385 | F11: =IF(D11>5000,"⭐ High",IF(D11>2000,"✅ Medium","🔻 Low")) -> ⭐ High
A12: Saree | B12: Clothing | C12: =COUNTIF('Cleaned Data'!E2:E81,A12) -> 1 | D12: =SUMIF('Cleaned Data'!E2:E81,A12,'Cleaned Data'!J2:J81) -> 4299.358 | E12: =IFERROR(AVERAGEIF('Cleaned Data'!E2:E81,A12,'Cleaned Data'!G2:G81),0) -> 4525.64 | F12: =IF(D12>5000,"⭐ High",IF(D12>2000,"✅ Medium","🔻 Low")) -> ✅ Medium
A13: Jacket | B13: Clothing | C13: =COUNTIF('Cleaned Data'!E2:E81,A13) -> 0 | D13: =SUMIF('Cleaned Data'!E2:E81,A13,'Cleaned Data'!J2:J81) -> 0 | E13: =IFERROR(AVERAGEIF('Cleaned Data'!E2:E81,A13,'Cleaned Data'!G2:G81),0) -> 0 | F13: =IF(D13>5000,"⭐ High",IF(D13>2000,"✅ Medium","🔻 Low")) -> 🔻 Low
A14: Mixer | B14: Home & Kitchen | C14: =COUNTIF('Cleaned Data'!E2:E81,A14) -> 2 | D14: =SUMIF('Cleaned Data'!E2:E81,A14,'Cleaned Data'!J2:J81) -> 10375.916 | E14: =IFERROR(AVERAGEIF('Cleaned Data'!E2:E81,A14,'Cleaned Data'!G2:G81),0) -> 3091.44 | F14: =IF(D14>5000,"⭐ High",IF(D14>2000,"✅ Medium","🔻 Low")) -> ⭐ High
A15: Pressure Cooker | B15: Home & Kitchen | C15: =COUNTIF('Cleaned Data'!E2:E81,A15) -> 1 | D15: =SUMIF('Cleaned Data'!E2:E81,A15,'Cleaned Data'!J2:J81) -> 2282.85 | E15: =IFERROR(AVERAGEIF('Cleaned Data'!E2:E81,A15,'Cleaned Data'!G2:G81),0) -> 507.3 | F15: =IF(D15>5000,"⭐ High",IF(D15>2000,"✅ Medium","🔻 Low")) -> ✅ Medium
A16: Bedsheet | B16: Home & Kitchen | C16: =COUNTIF('Cleaned Data'!E2:E81,A16) -> 4 | D16: =SUMIF('Cleaned Data'!E2:E81,A16,'Cleaned Data'!J2:J81) -> 45087.303 | E16: =IFERROR(AVERAGEIF('Cleaned Data'!E2:E81,A16,'Cleaned Data'!G2:G81),0) -> 1979.9175 | F16: =IF(D16>5000,"⭐ High",IF(D16>2000,"✅ Medium","🔻 Low")) -> ⭐ High
A17: Curtain | B17: Home & Kitchen | C17: =COUNTIF('Cleaned Data'!E2:E81,A17) -> 4 | D17: =SUMIF('Cleaned Data'!E2:E81,A17,'Cleaned Data'!J2:J81) -> 94945.295 | E17: =IFERROR(AVERAGEIF('Cleaned Data'!E2:E81,A17,'Cleaned Data'!G2:G81),0) -> 4590.955 | F17: =IF(D17>5000,"⭐ High",IF(D17>2000,"✅ Medium","🔻 Low")) -> ⭐ High
A18: Water Bottle | B18: Home & Kitchen | C18: =COUNTIF('Cleaned Data'!E2:E81,A18) -> 1 | D18: =SUMIF('Cleaned Data'!E2:E81,A18,'Cleaned Data'!J2:J81) -> 2206.048 | E18: =IFERROR(AVERAGEIF('Cleaned Data'!E2:E81,A18,'Cleaned Data'!G2:G81),0) -> 1378.78 | F18: =IF(D18>5000,"⭐ High",IF(D18>2000,"✅ Medium","🔻 Low")) -> ✅ Medium
A19: Cricket Bat | B19: Sports | C19: =COUNTIF('Cleaned Data'!E2:E81,A19) -> 3 | D19: =SUMIF('Cleaned Data'!E2:E81,A19,'Cleaned Data'!J2:J81) -> 53136.506 | E19: =IFERROR(AVERAGEIF('Cleaned Data'!E2:E81,A19,'Cleaned Data'!G2:G81),0) -> 5640.6933 | F19: =IF(D19>5000,"⭐ High",IF(D19>2000,"✅ Medium","🔻 Low")) -> ⭐ High
A20: Football | B20: Sports | C20: =COUNTIF('Cleaned Data'!E2:E81,A20) -> 4 | D20: =SUMIF('Cleaned Data'!E2:E81,A20,'Cleaned Data'!J2:J81) -> 74884.948 | E20: =IFERROR(AVERAGEIF('Cleaned Data'!E2:E81,A20,'Cleaned Data'!G2:G81),0) -> 3310.955 | F20: =IF(D20>5000,"⭐ High",IF(D20>2000,"✅ Medium","🔻 Low")) -> ⭐ High
A21: Yoga Mat | B21: Sports | C21: =COUNTIF('Cleaned Data'!E2:E81,A21) -> 4 | D21: =SUMIF('Cleaned Data'!E2:E81,A21,'Cleaned Data'!J2:J81) -> 120597.81 | E21: =IFERROR(AVERAGEIF('Cleaned Data'!E2:E81,A21,'Cleaned Data'!G2:G81),0) -> 4706.6375 | F21: =IF(D21>5000,"⭐ High",IF(D21>2000,"✅ Medium","🔻 Low")) -> ⭐ High
A22: Dumbbells | B22: Sports | C22: =COUNTIF('Cleaned Data'!E2:E81,A22) -> 5 | D22: =SUMIF('Cleaned Data'!E2:E81,A22,'Cleaned Data'!J2:J81) -> 117853.65 | E22: =IFERROR(AVERAGEIF('Cleaned Data'!E2:E81,A22,'Cleaned Data'!G2:G81),0) -> 4467.196 | F22: =IF(D22>5000,"⭐ High",IF(D22>2000,"✅ Medium","🔻 Low")) -> ⭐ High
A23: Badminton Racket | B23: Sports | C23: =COUNTIF('Cleaned Data'!E2:E81,A23) -> 0 | D23: =SUMIF('Cleaned Data'!E2:E81,A23,'Cleaned Data'!J2:J81) -> 0 | E23: =IFERROR(AVERAGEIF('Cleaned Data'!E2:E81,A23,'Cleaned Data'!G2:G81),0) -> 0 | F23: =IF(D23>5000,"⭐ High",IF(D23>2000,"✅ Medium","🔻 Low")) -> 🔻 Low
A24: Fiction Novel | B24: Books | C24: =COUNTIF('Cleaned Data'!E2:E81,A24) -> 1 | D24: =SUMIF('Cleaned Data'!E2:E81,A24,'Cleaned Data'!J2:J81) -> 10638.912 | E24: =IFERROR(AVERAGEIF('Cleaned Data'!E2:E81,A24,'Cleaned Data'!G2:G81),0) -> 4432.88 | F24: =IF(D24>5000,"⭐ High",IF(D24>2000,"✅ Medium","🔻 Low")) -> ⭐ High
A25: UPSC Guide | B25: Books | C25: =COUNTIF('Cleaned Data'!E2:E81,A25) -> 4 | D25: =SUMIF('Cleaned Data'!E2:E81,A25,'Cleaned Data'!J2:J81) -> 61379.311 | E25: =IFERROR(AVERAGEIF('Cleaned Data'!E2:E81,A25,'Cleaned Data'!G2:G81),0) -> 3379.3125 | F25: =IF(D25>5000,"⭐ High",IF(D25>2000,"✅ Medium","🔻 Low")) -> ⭐ High
A26: Python Book | B26: Books | C26: =COUNTIF('Cleaned Data'!E2:E81,A26) -> 3 | D26: =SUMIF('Cleaned Data'!E2:E81,A26,'Cleaned Data'!J2:J81) -> 28077.622 | E26: =IFERROR(AVERAGEIF('Cleaned Data'!E2:E81,A26,'Cleaned Data'!G2:G81),0) -> 4616.73 | F26: =IF(D26>5000,"⭐ High",IF(D26>2000,"✅ Medium","🔻 Low")) -> ⭐ High
A27: Comics | B27: Books | C27: =COUNTIF('Cleaned Data'!E2:E81,A27) -> 0 | D27: =SUMIF('Cleaned Data'!E2:E81,A27,'Cleaned Data'!J2:J81) -> 0 | E27: =IFERROR(AVERAGEIF('Cleaned Data'!E2:E81,A27,'Cleaned Data'!G2:G81),0) -> 0 | F27: =IF(D27>5000,"⭐ High",IF(D27>2000,"✅ Medium","🔻 Low")) -> 🔻 Low
A28: Self-Help | B28: Books | C28: =COUNTIF('Cleaned Data'!E2:E81,A28) -> 5 | D28: =SUMIF('Cleaned Data'!E2:E81,A28,'Cleaned Data'!J2:J81) -> 141465.8 | E28: =IFERROR(AVERAGEIF('Cleaned Data'!E2:E81,A28,'Cleaned Data'!G2:G81),0) -> 4868.848 | F28: =IF(D28>5000,"⭐ High",IF(D28>2000,"✅ Medium","🔻 Low")) -> ⭐ High
A29: Face Cream | B29: Beauty | C29: =COUNTIF('Cleaned Data'!E2:E81,A29) -> 3 | D29: =SUMIF('Cleaned Data'!E2:E81,A29,'Cleaned Data'!J2:J81) -> 50982.7 | E29: =IFERROR(AVERAGEIF('Cleaned Data'!E2:E81,A29,'Cleaned Data'!G2:G81),0) -> 2863.95 | F29: =IF(D29>5000,"⭐ High",IF(D29>2000,"✅ Medium","🔻 Low")) -> ⭐ High
A30: Shampoo | B30: Beauty | C30: =COUNTIF('Cleaned Data'!E2:E81,A30) -> 1 | D30: =SUMIF('Cleaned Data'!E2:E81,A30,'Cleaned Data'!J2:J81) -> 14235.12 | E30: =IFERROR(AVERAGEIF('Cleaned Data'!E2:E81,A30,'Cleaned Data'!G2:G81),0) -> 5931.3 | F30: =IF(D30>5000,"⭐ High",IF(D30>2000,"✅ Medium","🔻 Low")) -> ⭐ High
A31: Lipstick | B31: Beauty | C31: =COUNTIF('Cleaned Data'!E2:E81,A31) -> 2 | D31: =SUMIF('Cleaned Data'!E2:E81,A31,'Cleaned Data'!J2:J81) -> 40395.12 | E31: =IFERROR(AVERAGEIF('Cleaned Data'!E2:E81,A31,'Cleaned Data'!G2:G81),0) -> 3095.435 | F31: =IF(D31>5000,"⭐ High",IF(D31>2000,"✅ Medium","🔻 Low")) -> ⭐ High
A32: Sunscreen | B32: Beauty | C32: =COUNTIF('Cleaned Data'!E2:E81,A32) -> 1 | D32: =SUMIF('Cleaned Data'!E2:E81,A32,'Cleaned Data'!J2:J81) -> 34973.694 | E32: =IFERROR(AVERAGEIF('Cleaned Data'!E2:E81,A32,'Cleaned Data'!G2:G81),0) -> 4317.74 | F32: =IF(D32>5000,"⭐ High",IF(D32>2000,"✅ Medium","🔻 Low")) -> ⭐ High
A33: Perfume | B33: Beauty | C33: =COUNTIF('Cleaned Data'!E2:E81,A33) -> 3 | D33: =SUMIF('Cleaned Data'!E2:E81,A33,'Cleaned Data'!J2:J81) -> 28618.046 | E33: =IFERROR(AVERAGEIF('Cleaned Data'!E2:E81,A33,'Cleaned Data'!G2:G81),0) -> 1728.45 | F33: =IF(D33>5000,"⭐ High",IF(D33>2000,"✅ Medium","🔻 Low")) -> ⭐ High
A34: Lego Set | B34: Toys | C34: =COUNTIF('Cleaned Data'!E2:E81,A34) -> 0 | D34: =SUMIF('Cleaned Data'!E2:E81,A34,'Cleaned Data'!J2:J81) -> 0 | E34: =IFERROR(AVERAGEIF('Cleaned Data'!E2:E81,A34,'Cleaned Data'!G2:G81),0) -> 0 | F34: =IF(D34>5000,"⭐ High",IF(D34>2000,"✅ Medium","🔻 Low")) -> 🔻 Low
A35: Board Game | B35: Toys | C35: =COUNTIF('Cleaned Data'!E2:E81,A35) -> 1 | D35: =SUMIF('Cleaned Data'!E2:E81,A35,'Cleaned Data'!J2:J81) -> 6110.216 | E35: =IFERROR(AVERAGEIF('Cleaned Data'!E2:E81,A35,'Cleaned Data'!G2:G81),0) -> 1091.11 | F35: =IF(D35>5000,"⭐ High",IF(D35>2000,"✅ Medium","🔻 Low")) -> ⭐ High
A36: RC Car | B36: Toys | C36: =COUNTIF('Cleaned Data'!E2:E81,A36) -> 3 | D36: =SUMIF('Cleaned Data'!E2:E81,A36,'Cleaned Data'!J2:J81) -> 30211.058 | E36: =IFERROR(AVERAGEIF('Cleaned Data'!E2:E81,A36,'Cleaned Data'!G2:G81),0) -> 3917.58 | F36: =IF(D36>5000,"⭐ High",IF(D36>2000,"✅ Medium","🔻 Low")) -> ⭐ High
A37: Doll | B37: Toys | C37: =COUNTIF('Cleaned Data'!E2:E81,A37) -> 5 | D37: =SUMIF('Cleaned Data'!E2:E81,A37,'Cleaned Data'!J2:J81) -> 44503.651 | E37: =IFERROR(AVERAGEIF('Cleaned Data'!E2:E81,A37,'Cleaned Data'!G2:G81),0) -> 3118.902 | F37: =IF(D37>5000,"⭐ High",IF(D37>2000,"✅ Medium","🔻 Low")) -> ⭐ High
A38: Puzzle | B38: Toys | C38: =COUNTIF('Cleaned Data'!E2:E81,A38) -> 3 | D38: =SUMIF('Cleaned Data'!E2:E81,A38,'Cleaned Data'!J2:J81) -> 80299.758 | E38: =IFERROR(AVERAGEIF('Cleaned Data'!E2:E81,A38,'Cleaned Data'!G2:G81),0) -> 6161.5867 | F38: =IF(D38>5000,"⭐ High",IF(D38>2000,"✅ Medium","🔻 Low")) -> ⭐ High
